Workbook

Sheet META
A1: META | E1: PRODUÇÃO NO PERÍODO | L1: VENDA ESTIMADA PARA OUTUBRO
A2: Amanda | B2: 4500
A3: Bruna | B3: 18000
A4: Camila | B4: 15000 | E4: Corretores | F4: Valor | G4: Meta | H4: Valor que falta | I4: % Atual | J4: % Que falta | L4: Corretores | M4: Valor | N4: Meta | O4: Valor que falta | P4: % Atual | Q4: % Que falta
A5: Darlin | B5: 3000 | E5: Amanda Facundo | F5: =IFERROR( SUMIFS('Amanda Facundo'!$H:$H, 'Amanda Facundo'!$G:$G, "Plano Fechado", 'Amanda Facundo'!$I:$I, ">=01/10/2025", 'Amanda Facundo'!$I:$I, "<01/11/2025") + SUMIFS('Amanda Facundo'!$H:$H, 'Amanda Facundo'!$G:$G, "Aguardando Pagamento", 'Amanda Facundo'!$I:$I, ">=01/10/2025", 'Amanda Facundo'!$I:$I, "<01/11/2025") + SUMIFS('Amanda Facundo'!$H:$H, 'Amanda Facundo'!$G:$G, "Em Análise", 'Amanda Facundo'!$I:$I, ">=01/10/2025", 'Amanda Facundo'!$I:$I, "<01/11/2025"), "") -> 686.05 | G5: 4500 | H5: =G5-F5 -> 3813.95 | I5: =F5/G5 -> 0.15245556 | J5: =H5/G5 -> 0.84754444 | L5: Amanda Facundo | M5: =IFERROR( SUMIFS('Amanda Facundo'!$H:$H, 'Amanda Facundo'!$G:$G, "Plano Fechado", 'Amanda Facundo'!$L:$L, "=10") + SUMIFS('Amanda Facundo'!$H:$H, 'Amanda Facundo'!$G:$G, "Aguardando Pagamento", 'Amanda Facundo'!$L:$L, "=10") + SUMIFS('Amanda Facundo'!$H:$H, 'Amanda Facundo'!$G:$G, "Em Análise", 'Amanda Facundo'!$L:$L, "=10"), "") -> 686.05 | N5: 4500 | O5: =N5-M5 -> 3813.95 | P5: =M5/N5 -> 0.15245556 | Q5: =O5/N5 -> 0.84754444
A6: Diogo | B6: 15000 | E6: Bruna Mamedes | F6: =IFERROR( SUMIFS('Bruna Mamedes'!$H:$H, 'Bruna Mamedes'!$G:$G, "Plano Fechado", 'Bruna Mamedes'!$I:$I, ">=01/10/2025", 'Bruna Mamedes'!$I:$I, "<01/11/2025") + SUMIFS('Bruna Mamedes'!$H:$H, 'Bruna Mamedes'!$G:$G, "Aguardando Pagamento", 'Bruna Mamedes'!$I:$I, ">=01/10/2025", 'Bruna Mamedes'!$I:$I, "<01/11/2025") + SUMIFS('Bruna Mamedes'!$H:$H, 'Bruna Mamedes'!$G:$G, "Em Análise", 'Bruna Mamedes'!$I:$I, ">=01/10/2025", 'Bruna Mamedes'!$I:$I, "<01/11/2025"), "") -> 18083.72 | G6: 18000 | H6: =G6-F6 -> -83.72 | I6: =F6/G6 -> 1.0046511 | J6: =H6/G6 -> -0.0046511111 | L6: Bruna Mamedes | M6: =IFERROR( SUMIFS('Bruna Mamedes'!$H:$H, 'Bruna Mamedes'!$G:$G, "Plano Fechado", 'Bruna Mamedes'!$L:$L, "=10") + SUMIFS('Bruna Mamedes'!$H:$H, 'Bruna Mamedes'!$G:$G, "Aguardando Pagamento", 'Bruna Mamedes'!$L:$L, "=10") + SUMIFS('Bruna Mamedes'!$H:$H, 'Bruna Mamedes'!$G:$G, "Em Análise", 'Bruna Mamedes'!$L:$L, "=10"), "") -> 17622.55 | N6: 18000 | O6: =N6-M6 -> 377.45 | P6: =M6/N6 -> 0.97903056 | Q6: =O6/N6 -> 0.020969444
A7: Externo | B7: 18000 | E7: Camila Adão | F7: =IFERROR( SUMIFS('Camila Adão'!$H:$H, 'Camila Adão'!$G:$G, "Plano Fechado", 'Camila Adão'!$I:$I, ">=01/10/2025", 'Camila Adão'!$I:$I, "<01/11/2025") + SUMIFS('Camila Adão'!$H:$H, 'Camila Adão'!$G:$G, "Aguardando Pagamento", 'Camila Adão'!$I:$I, ">=01/10/2025", 'Camila Adão'!$I:$I, "<01/11/2025") + SUMIFS('Camila Adão'!$H:$H, 'Camila Adão'!$G:$G, "Em Análise", 'Camila Adão'!$I:$I, ">=01/10/2025", 'Camila Adão'!$I:$I, "<01/11/2025"), "") -> 18337.98 | G7: 15000 | H7: =G7-F7 -> -3337.98 | I7: =F7/G7 -> 1.222532 | J7: =H7/G7 -> -0.222532 | L7: Camila Adão | M7: =IFERROR( SUMIFS('Camila Adão'!$H:$H, 'Camila Adão'!$G:$G, "Plano Fechado", 'Camila Adão'!$L:$L, "=10") + SUMIFS('Camila Adão'!$H:$H, 'Camila Adão'!$G:$G, "Aguardando Pagamento", 'Camila Adão'!$L:$L, "=10") + SUMIFS('Camila Adão'!$H:$H, 'Camila Adão'!$G:$G, "Em Análise", 'Camila Adão'!$L:$L, "=10"), "") -> 17293.72 | N7: 15000 | O7: =N7-M7 -> -2293.72 | P7: =M7/N7 -> 1.1529147 | Q7: =O7/N7 -> -0.15291467
A8: Maiara | B8: 18000 | E8: Darlin Amorim | F8: =IFERROR( SUMIFS('Darlin Amorim'!$H:$H, 'Darlin Amorim'!$G:$G, "Plano Fechado", 'Darlin Amorim'!$I:$I, ">=01/10/2025", 'Darlin Amorim'!$I:$I, "<01/11/2025") + SUMIFS('Darlin Amorim'!$H:$H, 'Darlin Amorim'!$G:$G, "Aguardando Pagamento", 'Darlin Amorim'!$I:$I, ">=01/10/2025", 'Darlin Amorim'!$I:$I, "<01/11/2025") + SUMIFS('Darlin Amorim'!$H:$H, 'Darlin Amorim'!$G:$G, "Em Análise", 'Darlin Amorim'!$I:$I, ">=01/10/2025", 'Darlin Amorim'!$I:$I, "<01/11/2025"), "") -> 586 | G8: 3000 | H8: =G8-F8 -> 2414 | I8: =F8/G8 -> 0.19533333 | J8: =H8/G8 -> 0.80466667 | L8: Darlin Amorim | M8: =IFERROR( SUMIFS('Darlin Amorim'!$H:$H, 'Darlin Amorim'!$G:$G, "Plano Fechado", 'Darlin Amorim'!$L:$L, "=10") + SUMIFS('Darlin Amorim'!$H:$H, 'Darlin Amorim'!$G:$G, "Aguardando Pagamento", 'Darlin Amorim'!$L:$L, "=10") + SUMIFS('Darlin Amorim'!$H:$H, 'Darlin Amorim'!$G:$G, "Em Análise", 'Darlin Amorim'!$L:$L, "=10"), "") -> 0 | N8: 3000 | O8: =N8-M8 -> 3000 | P8: =M8/N8 -> 0 | Q8: =O8/N8 -> 1
A9: Marcio | B9: 12000 | E9: Diogo Lima | F9: =IFERROR( SUMIFS('Diogo Lima'!$H:$H, 'Diogo Lima'!$G:$G, "Plano Fechado", 'Diogo Lima'!$I:$I, ">=01/10/2025", 'Diogo Lima'!$I:$I, "<01/11/2025") + SUMIFS('Diogo Lima'!$H:$H, 'Diogo Lima'!$G:$G, "Aguardando Pagamento", 'Diogo Lima'!$I:$I, ">=01/10/2025", 'Diogo Lima'!$I:$I, "<01/11/2025") + SUMIFS('Diogo Lima'!$H:$H, 'Diogo Lima'!$G:$G, "Em Análise", 'Diogo Lima'!$I:$I, ">=01/10/2025", 'Diogo Lima'!$I:$I, "<01/11/2025"), "") -> 9964.09 | G9: 15000 | H9: =G9-F9 -> 5035.91 | I9: =F9/G9 -> 0.66427267 | J9: =H9/G9 -> 0.33572733 | L9: Diogo Lima | M9: =IFERROR( SUMIFS('Diogo Lima'!$H:$H, 'Diogo Lima'!$G:$G, "Plano Fechado", 'Diogo Lima'!$L:$L, "=10") + SUMIFS('Diogo Lima'!$H:$H, 'Diogo Lima'!$G:$G, "Aguardando Pagamento", 'Diogo Lima'!$L:$L, "=10") + SUMIFS('Diogo Lima'!$H:$H, 'Diogo Lima'!$G:$G, "Em Análise", 'Diogo Lima'!$L:$L, "=10"), "") -> 10430.14 | N9: 15000 | O9: =N9-M9 -> 4569.86 | P9: =M9/N9 -> 0.69534267 | Q9: =O9/N9 -> 0.30465733
A10: Roberto | B10: 14000 | E10: Externos | F10: =IFERROR( SUMIFS('Fernando Diamantino'!$H:$H, 'Fernando Diamantino'!$G:$G, "Plano Fechado", 'Fernando Diamantino'!$I:$I, ">=01/10/2025", 'Fernando Diamantino'!$I:$I, "<01/11/2025") + SUMIFS('Fernando Diamantino'!$H:$H, 'Fernando Diamantino'!$G:$G, "Aguardando Pagamento", 'Fernando Diamantino'!$I:$I, ">=01/10/2025", 'Fernando Diamantino'!$I:$I, "<01/11/2025") + SUMIFS('Fernando Diamantino'!$H:$H, 'Fernando Diamantino'!$G:$G, "Em Análise", 'Fernando Diamantino'!$I:$I, ">=01/10/2025", 'Fernando Diamantino'!$I:$I, "<01/11/2025"), "") -> 4445.86 | G10: 18000 | H10: =G10-F10 -> 13554.14 | I10: =F10/G10 -> 0.24699222 | J10: =H10/G10 -> 0.75300778 | L10: Externos | M10: =IFERROR( SUMIFS('Fernando Diamantino'!$H:$H, 'Fernando Diamantino'!$G:$G, "Plano Fechado", 'Fernando Diamantino'!$L:$L, "=10") + SUMIFS('Fernando Diamantino'!$H:$H, 'Fernando Diamantino'!$G:$G, "Aguardando Pagamento", 'Fernando Diamantino'!$L:$L, "=10") + SUMIFS('Fernando Diamantino'!$H:$H, 'Fernando Diamantino'!$G:$G, "Em Análise", 'Fernando Diamantino'!$L:$L, "=10"), "") -> 15547.74 | N10: 18000 | O10: =N10-M10 -> 2452.26 | P10: =M10/N10 -> 0.86376333 | Q10: =O10/N10 -> 0.13623667
A11: Rodrigo | B11: 4000 | E11: Maiara Andrade | F11: =IFERROR( SUMIFS('Maiara Andrade'!$H:$H, 'Maiara Andrade'!$G:$G, "Plano Fechado", 'Maiara Andrade'!$I:$I, ">=01/10/2025", 'Maiara Andrade'!$I:$I, "<01/11/2025") + SUMIFS('Maiara Andrade'!$H:$H, 'Maiara Andrade'!$G:$G, "Aguardando Pagamento", 'Maiara Andrade'!$I:$I, ">=01/10/2025", 'Maiara Andrade'!$I:$I, "<01/11/2025") + SUMIFS('Maiara Andrade'!$H:$H, 'Maiara Andrade'!$G:$G, "Em Análise", 'Maiara Andrade'!$I:$I, ">=01/10/2025", 'Maiara Andrade'!$I:$I, "<01/11/2025"), "") -> 8595.5 | G11: 18000 | H11: =G11-F11 -> 9404.5 | I11: =F11/G11 -> 0.47752778 | J11: =H11/G11 -> 0.52247222 | L11: Maiara Andrade | M11: =IFERROR( SUMIFS('Maiara Andrade'!$H:$H, 'Maiara Andrade'!$G:$G, "Plano Fechado", 'Maiara Andrade'!$L:$L, "=10") + SUMIFS('Maiara Andrade'!$H:$H, 'Maiara Andrade'!$G:$G, "Aguardando Pagamento", 'Maiara Andrade'!$L:$L, "=10") + SUMIFS('Maiara Andrade'!$H:$H, 'Maiara Andrade'!$G:$G, "Em Análise", 'Maiara Andrade'!$L:$L, "=10"), "") -> 18640.44 | N11: 18000 | O11: =N11-M11 -> -640.44 | P11: =M11/N11 -> 1.03558 | Q11: =O11/N11 -> -0.03558
A12: Leandro Nascimento | B12: 2800 | E12: Marcio Jorge | F12: =IFERROR( SUMIFS('Marcio Jorge'!$H:$H, 'Marcio Jorge'!$G:$G, "Plano Fechado", 'Marcio Jorge'!$I:$I, ">=01/10/2025", 'Marcio Jorge'!$I:$I, "<01/11/2025") + SUMIFS('Marcio Jorge'!$H:$H, 'Marcio Jorge'!$G:$G, "Aguardando Pagamento", 'Marcio Jorge'!$I:$I, ">=01/10/2025", 'Marcio Jorge'!$I:$I, "<01/11/2025") + SUMIFS('Marcio Jorge'!$H:$H, 'Marcio Jorge'!$G:$G, "Em Análise", 'Marcio Jorge'!$I:$I, ">=01/10/2025", 'Marcio Jorge'!$I:$I, "<01/11/2025"), "") -> 5283.78 | G12: 12000 | H12: =G12-F12 -> 6716.22 | I12: =F12/G12 -> 0.440315 | J12: =H12/G12 -> 0.559685 | L12: Marcio Jorge | M12: =IFERROR( SUMIFS('Marcio Jorge'!$H:$H, 'Marcio Jorge'!$G:$G, "Plano Fechado", 'Marcio Jorge'!$L:$L, "=10") + SUMIFS('Marcio Jorge'!$H:$H, 'Marcio Jorge'!$G:$G, "Aguardando Pagamento", 'Marcio Jorge'!$L:$L, "=10") + SUMIFS('Marcio Jorge'!$H:$H, 'Marcio Jorge'!$G:$G, "Em Análise", 'Marcio Jorge'!$L:$L, "=10"), "") -> 10794.91 | N12: 12000 | O12: =N12-M12 -> 1205.09 | P12: =M12/N12 -> 0.89957583 | Q12: =O12/N12 -> 0.10042417
A13: Leandro Drumond | B13: 4500 | E13: Lucas Almeida | F13: =IFERROR( SUMIFS('Lucas Almeida'!$H:$H, 'Lucas Almeida'!$G:$G, "Plano Fechado", 'Lucas Almeida'!$I:$I, ">=01/10/2025", 'Lucas Almeida'!$I:$I, "<01/11/2025") + SUMIFS('Lucas Almeida'!$H:$H, 'Lucas Almeida'!$G:$G, "Aguardando Pagamento", 'Lucas Almeida'!$I:$I, ">=01/10/2025", 'Lucas Almeida'!$I:$I, "<01/11/2025") + SUMIFS('Lucas Almeida'!$H:$H, 'Lucas Almeida'!$G:$G, "Em Análise", 'Lucas Almeida'!$I:$I, ">=01/10/2025", 'Lucas Almeida'!$I:$I, "<01/11/2025"), "") -> 0 | G13: 4500 | H13: =G13-F13 -> 4500 | I13: =F13/G13 -> 0 | J13: =H13/G13 -> 1 | L13: Lucas Almeida | M13: =IFERROR( SUMIFS('Lucas Almeida'!$H:$H, 'Lucas Almeida'!$G:$G, "Plano Fechado", 'Lucas Almeida'!$L:$L, "=10") + SUMIFS('Lucas Almeida'!$H:$H, 'Lucas Almeida'!$G:$G, "Aguardando Pagamento", 'Lucas Almeida'!$L:$L, "=10") + SUMIFS('Lucas Almeida'!$H:$H, 'Lucas Almeida'!$G:$G, "Em Análise", 'Lucas Almeida'!$L:$L, "=10"), "") -> 1963.8 | N13: 4500 | O13: =N13-M13 -> 2536.2 | P13: =M13/N13 -> 0.4364 | Q13: =O13/N13 -> 0.5636
A14: Mauro | B14: 2800 | E14: Roberto Ramos | F14: =IFERROR( SUMIFS('Roberto Ramos'!$H:$H, 'Roberto Ramos'!$G:$G, "Plano Fechado", 'Roberto Ramos'!$I:$I, ">=01/10/2025", 'Roberto Ramos'!$I:$I, "<01/11/2025") + SUMIFS('Roberto Ramos'!$H:$H, 'Roberto Ramos'!$G:$G, "Aguardando Pagamento", 'Roberto Ramos'!$I:$I, ">=01/10/2025", 'Roberto Ramos'!$I:$I, "<01/11/2025") + SUMIFS('Roberto Ramos'!$H:$H, 'Roberto Ramos'!$G:$G, "Em Análise", 'Roberto Ramos'!$I:$I, ">=01/10/2025", 'Roberto Ramos'!$I:$I, "<01/11/2025"), "") -> 7459.98 | G14: 14000 | H14: =G14-F14 -> 6540.02 | I14: =F14/G14 -> 0.53285571 | J14: =H14/G14 -> 0.46714429 | L14: Roberto Ramos | M14: =IFERROR( SUMIFS('Roberto Ramos'!$H:$H, 'Roberto Ramos'!$G:$G, "Plano Fechado", 'Roberto Ramos'!$L:$L, "=10") + SUMIFS('Roberto Ramos'!$H:$H, 'Roberto Ramos'!$G:$G, "Aguardando Pagamento", 'Roberto Ramos'!$L:$L, "=10") + SUMIFS('Roberto Ramos'!$H:$H, 'Roberto Ramos'!$G:$G, "Em Análise", 'Roberto Ramos'!$L:$L, "=10"), "") -> 8641.16 | N14: 14000 | O14: =N14-M14 -> 5358.84 | P14: =M14/N14 -> 0.61722571 | Q14: =O14/N14 -> 0.38277429
A15: Lucas | B15: 4500 | E15: Rodrigo Oliviera | F15: =IFERROR( SUMIFS('Rodrigo Oliveira'!$H:$H, 'Rodrigo Oliveira'!$G:$G, "Plano Fechado", 'Rodrigo Oliveira'!$I:$I, ">=01/10/2025", 'Rodrigo Oliveira'!$I:$I, "<01/11/2025") + SUMIFS('Rodrigo Oliveira'!$H:$H, 'Rodrigo Oliveira'!$G:$G, "Aguardando Pagamento", 'Rodrigo Oliveira'!$I:$I, ">=01/10/2025", 'Rodrigo Oliveira'!$I:$I, "<01/11/2025") + SUMIFS('Rodrigo Oliveira'!$H:$H, 'Rodrigo Oliveira'!$G:$G, "Em Análise", 'Rodrigo Oliveira'!$I:$I, ">=01/10/2025", 'Rodrigo Oliveira'!$I:$I, "<01/11/2025"), "") -> 3284.71 | G15: 4000 | H15: =G15-F15 -> 715.29 | I15: =F15/G15 -> 0.8211775 | J15: =H15/G15 -> 0.1788225 | L15: Rodrigo Oliviera | M15: =IFERROR( SUMIFS('Rodrigo Oliveira'!$H:$H, 'Rodrigo Oliveira'!$G:$G, "Plano Fechado", 'Rodrigo Oliveira'!$L:$L, "=10") + SUMIFS('Rodrigo Oliveira'!$H:$H, 'Rodrigo Oliveira'!$G:$G, "Aguardando Pagamento", 'Rodrigo Oliveira'!$L:$L, "=10") + SUMIFS('Rodrigo Oliveira'!$H:$H, 'Rodrigo Oliveira'!$G:$G, "Em Análise", 'Rodrigo Oliveira'!$L:$L, "=10"), "") -> 0 | N15: 4000 | O15: =N15-M15 -> 4000 | P15: =M15/N15 -> 0 | Q15: =O15/N15 -> 1
E16: Leandro Nascimento | F16: =IFERROR( SUMIFS('Leandro Nascimento'!$H:$H, 'Leandro Nascimento'!$G:$G, "Plano Fechado", 'Leandro Nascimento'!$I:$I, ">=01/10/2025", 'Leandro Nascimento'!$I:$I, "<01/11/2025") + SUMIFS('Leandro Nascimento'!$H:$H, 'Leandro Nascimento'!$G:$G, "Aguardando Pagamento", 'Leandro Nascimento'!$I:$I, ">=01/10/2025", 'Leandro Nascimento'!$I:$I, "<01/11/2025") + SUMIFS('Leandro Nascimento'!$H:$H, 'Leandro Nascimento'!$G:$G, "Em Análise", 'Leandro Nascimento'!$I:$I, ">=01/10/2025", 'Leandro Nascimento'!$I:$I, "<01/11/2025"), "") -> 0 | G16: 2800 | H16: =G16-F16 -> 2800 | I16: =F16/G16 -> 0 | J16: =H16/G16 -> 1 | L16: Leandro Nascimento | M16: =IFERROR( SUMIFS('Leandro Nascimento'!$H:$H, 'Leandro Nascimento'!$G:$G, "Plano Fechado", 'Leandro Nascimento'!$L:$L, "=10") + SUMIFS('Leandro Nascimento'!$H:$H, 'Leandro Nascimento'!$G:$G, "Aguardando Pagamento", 'Leandro Nascimento'!$L:$L, "=10") + SUMIFS('Leandro Nascimento'!$H:$H, 'Leandro Nascimento'!$G:$G, "Em Análise", 'Leandro Nascimento'!$L:$L, "=10"), "") -> 1578.6 | N16: 2800 | O16: =N16-M16 -> 1221.4 | P16: =M16/N16 -> 0.56378571 | Q16: =O16/N16 -> 0.43621429
E17: Leandro Drumond | F17: =IFERROR( SUMIFS('Leandro Drumond'!$H:$H, 'Leandro Drumond'!$G:$G, "Plano Fechado", 'Leandro Drumond'!$I:$I, ">=01/10/2025", 'Leandro Drumond'!$I:$I, "<01/11/2025") + SUMIFS('Leandro Drumond'!$H:$H, 'Leandro Drumond'!$G:$G, "Aguardando Pagamento", 'Leandro Drumond'!$I:$I, ">=01/10/2025", 'Leandro Drumond'!$I:$I, "<01/11/2025") + SUMIFS('Leandro Drumond'!$H:$H, 'Leandro Drumond'!$G:$G, "Em Análise", 'Leandro Drumond'!$I:$I, ">=01/10/2025", 'Leandro Drumond'!$I:$I, "<01/11/2025"), "") -> 0 | G17: 4500 | H17: =G17-F17 -> 4500 | I17: =F17/G17 -> 0 | J17: =H17/G17 -> 1 | L17: Leandro Drumond | M17: =IFERROR( SUMIFS('Leandro Drumond'!$H:$H, 'Leandro Drumond'!$G:$G, "Plano Fechado", 'Leandro Drumond'!$L:$L, "=10") + SUMIFS('Leandro Drumond'!$H:$H, 'Leandro Drumond'!$G:$G, "Aguardando Pagamento", 'Leandro Drumond'!$L:$L, "=10") + SUMIFS('Leandro Drumond'!$H:$H, 'Leandro Drumond'!$G:$G, "Em Análise", 'Leandro Drumond'!$L:$L, "=10"), "") -> 0 | N17: 4500 | O17: =N17-M17 -> 4500 | P17: =M17/N17 -> 0 | Q17: =O17/N17 -> 1
E18: Marcelle Marcela | F18: =IFERROR( SUMIFS('Marcelle Marcela'!$H:$H, 'Marcelle Marcela'!$G:$G, "Plano Fechado", 'Marcelle Marcela'!$I:$I, ">=01/10/2025", 'Marcelle Marcela'!$I:$I, "<01/11/2025") + SUMIFS('Marcelle Marcela'!$H:$H, 'Marcelle Marcela'!$G:$G, "Aguardando Pagamento", 'Marcelle Marcela'!$I:$I, ">=01/10/2025", 'Marcelle Marcela'!$I:$I, "<01/11/2025") + SUMIFS('Marcelle Marcela'!$H:$H, 'Marcelle Marcela'!$G:$G, "Em Análise", 'Marcelle Marcela'!$I:$I, ">=01/10/2025", 'Marcelle Marcela'!$I:$I, "<01/11/2025"), "") -> 0 | G18: 2800 | H18: =G18-F18 -> 2800 | I18: =F18/G18 -> 0 | J18: =H18/G18 -> 1 | L18: Marcelle Marcela | M18: =IFERROR( SUMIFS('Marcelle Marcela'!$H:$H, 'Marcelle Marcela'!$G:$G, "Plano Fechado", 'Marcelle Marcela'!$L:$L, "=10") + SUMIFS('Marcelle Marcela'!$H:$H, 'Marcelle Marcela'!$G:$G, "Aguardando Pagamento", 'Marcelle Marcela'!$L:$L, "=10") + SUMIFS('Marcelle Marcela'!$H:$H, 'Marcelle Marcela'!$G:$G, "Em Análise", 'Marcelle Marcela'!$L:$L, "=10"), "") -> 0 | N18: 2800 | O18: =N18-M18 -> 2800 | P18: =M18/N18 -> 0 | Q18: =O18/N18 -> 1
E21: TOTAL | F21: =SUM(F5:F18) -> 76727.67 | G21: =SUM(G5:G18) -> 136100 | H21: =SUM(H5:H18) -> 59372.33 | I21: =AVERAGE(I5:I18) -> 0.41129378 | J21: =AVERAGE(J5:J18) -> 0.58870622 | L21: TOTAL | M21: =SUM(M5:M18) -> 103199.11 | N21: =SUM(N5:N18) -> 136100 | O21: =SUM(O5:O18) -> 32900.89 | P21: =AVERAGE(P5:P18) -> 0.528291 | Q21: =AVERAGE(Q5:Q18) -> 0.471709
A26: VENDA FECHADA PARA OUTUBRO | H26: VENDA EM ANÁLISE PARA OUTUBRO | O26: VENDA À QUITAÇÃO PARA OUTUBRO
A29: Corretores | B29: Valor | C29: Meta | D29: Valor que falta | E29: % Atual | F29: % Que falta | H29: Corretores | I29: Valor | J29: Meta | K29: Valor que falta | L29: % Atual | M29: % Que falta | O29: Corretores | P29: Valor | Q29: Meta | R29: Valor que falta | S29: % Atual | T29: % Que falta
A30: Amanda Facundo | B30: =IFERROR( SUMIFS('Amanda Facundo'!$H:$H, 'Amanda Facundo'!$G:$G, "Plano Fechado", 'Amanda Facundo'!$L:$L, "=10"), "") -> 686.05 | C30: 4500 | D30: =C30-B30 -> 3813.95 | E30: =B30/C30 -> 0.15245556 | F30: =D30/C30 -> 0.84754444 | H30: Amanda Facundo | I30: =IFERROR( SUMIFS('Amanda Facundo'!$H:$H, 'Amanda Facundo'!$G:$G, "Em Análise", 'Amanda Facundo'!$L:$L, "=10"), "") -> 0 | J30: 4500 | K30: =J30-I30 -> 4500 | L30: =I30/J30 -> 0 | M30: =K30/J30 -> 1 | O30: Amanda Facundo | P30: =IFERROR( SUMIFS('Amanda Facundo'!$H:$H, 'Amanda Facundo'!$G:$G, "Aguardando Pagamento", 'Amanda Facundo'!$L:$L, "=10"), "") -> 0 | Q30: 4500 | R30: =Q30-P30 -> 4500 | S30: =P30/Q30 -> 0 | T30: =R30/Q30 -> 1
A31: Bruna Mamedes | B31: =IFERROR( SUMIFS('Bruna Mamedes'!$H:$H, 'Bruna Mamedes'!$G:$G, "Plano Fechado", 'Bruna Mamedes'!$L:$L, "=10"), "") -> 12816.45 | C31: 18000 | D31: =C31-B31 -> 5183.55 | E31: =B31/C31 -> 0.712025 | F31: =D31/C31 -> 0.287975 | H31: Bruna Mamedes | I31: =IFERROR( SUMIFS('Bruna Mamedes'!$H:$H, 'Bruna Mamedes'!$G:$G, "Em Análise", 'Bruna Mamedes'!$L:$L, "=10"), "") -> 4806.1 | J31: 18000 | K31: =J31-I31 -> 13193.9 | L31: =I31/J31 -> 0.26700556 | M31: =K31/J31 -> 0.73299444 | O31: Bruna Mamedes | P31: =IFERROR( SUMIFS('Bruna Mamedes'!$H:$H, 'Bruna Mamedes'!$G:$G, "Aguardando Pagamento", 'Bruna Mamedes'!$L:$L, "=10"), "") -> 0 | Q31: 18000 | R31: =Q31-P31 -> 18000 | S31: =P31/Q31 -> 0 | T31: =R31/Q31 -> 1
A32: Camila Adão | B32: =IFERROR( SUMIFS('Camila Adão'!$H:$H, 'Camila Adão'!$G:$G, "Plano Fechado", 'Camila Adão'!$L:$L, "=10"), "") -> 17293.72 | C32: 15000 | D32: =C32-B32 -> -2293.72 | E32: =B32/C32 -> 1.1529147 | F32: =D32/C32 -> -0.15291467 | H32: Camila Adão | I32: =IFERROR( SUMIFS('Camila Adão'!$H:$H, 'Camila Adão'!$G:$G, "Em Análise", 'Camila Adão'!$L:$L, "=10"), "") -> 0 | J32: 15000 | K32: =J32-I32 -> 15000 | L32: =I32/J32 -> 0 | M32: =K32/J32 -> 1 | O32: Camila Adão | P32: =IFERROR( SUMIFS('Camila Adão'!$H:$H, 'Camila Adão'!$G:$G, "Aguardando Pagamento", 'Camila Adão'!$L:$L, "=10"), "") -> 0 | Q32: 15000 | R32: =Q32-P32 -> 15000 | S32: =P32/Q32 -> 0 | T32: =R32/Q32 -> 1
A33: Darlin Amorim | B33: =IFERROR( SUMIFS('Darlin Amorim'!$H:$H, 'Darlin Amorim'!$G:$G, "Plano Fechado", 'Darlin Amorim'!$L:$L, "=10"), "") -> 0 | C33: 3000 | D33: =C33-B33 -> 3000 | E33: =B33/C33 -> 0 | F33: =D33/C33 -> 1 | H33: Darlin Amorim | I33: =IFERROR( SUMIFS('Darlin Amorim'!$H:$H, 'Darlin Amorim'!$G:$G, "Em Análise", 'Darlin Amorim'!$L:$L, "=10"), "") -> 0 | J33: 3000 | K33: =J33-I33 -> 3000 | L33: =I33/J33 -> 0 | M33: =K33/J33 -> 1 | O33: Darlin Amorim | P33: =IFERROR( SUMIFS('Darlin Amorim'!$H:$H, 'Darlin Amorim'!$G:$G, "Aguardando Pagamento", 'Darlin Amorim'!$L:$L, "=10"), "") -> 0 | Q33: 3000 | R33: =Q33-P33 -> 3000 | S33: =P33/Q33 -> 0 | T33: =R33/Q33 -> 1
A34: Diogo Lima | B34: =IFERROR( SUMIFS('Diogo Lima'!$H:$H, 'Diogo Lima'!$G:$G, "Plano Fechado", 'Diogo Lima'!$L:$L, "=10"), "") -> 10430.14 | C34: 15000 | D34: =C34-B34 -> 4569.86 | E34: =B34/C34 -> 0.69534267 | F34: =D34/C34 -> 0.30465733 | H34: Diogo Lima | I34: =IFERROR( SUMIFS('Diogo Lima'!$H:$H, 'Diogo Lima'!$G:$G, "Em Análise", 'Diogo Lima'!$L:$L, "=10"), "") -> 0 | J34: 15000 | K34: =J34-I34 -> 15000 | L34: =I34/J34 -> 0 | M34: =K34/J34 -> 1 | O34: Diogo Lima | P34: =IFERROR( SUMIFS('Diogo Lima'!$H:$H, 'Diogo Lima'!$G:$G, "Aguardando Pagamento", 'Diogo Lima'!$L:$L, "=10"), "") -> 0 | Q34: 15000 | R34: =Q34-P34 -> 15000 | S34: =P34/Q34 -> 0 | T34: =R34/Q34 -> 1
A35: Externos | B35: =IFERROR( SUMIFS('Fernando Diamantino'!$H:$H, 'Fernando Diamantino'!$G:$G, "Plano Fechado", 'Fernando Diamantino'!$L:$L, "=10"), "") -> 15547.74 | C35: 18000 | D35: =C35-B35 -> 2452.26 | E35: =B35/C35 -> 0.86376333 | F35: =D35/C35 -> 0.13623667 | H35: Externos | I35: =IFERROR( SUMIFS('Fernando Diamantino'!$H:$H, 'Fernando Diamantino'!$G:$G, "Em Análise", 'Fernando Diamantino'!$L:$L, "=10"), "") -> 0 | J35: 18000 | K35: =J35-I35 -> 18000 | L35: =I35/J35 -> 0 | M35: =K35/J35 -> 1 | O35: Externos | P35: =IFERROR( SUMIFS('Fernando Diamantino'!$H:$H, 'Fernando Diamantino'!$G:$G, "Aguardando Pagamento", 'Fernando Diamantino'!$L:$L, "=10"), "") -> 0 | Q35: 18000 | R35: =Q35-P35 -> 18000 | S35: =P35/Q35 -> 0 | T35: =R35/Q35 -> 1
A36: Maiara Andrade | B36: =IFERROR( SUMIFS('Maiara Andrade'!$H:$H, 'Maiara Andrade'!$G:$G, "Plano Fechado", 'Maiara Andrade'!$L:$L, "=10"), "") -> 12378.43 | C36: 18000 | D36: =C36-B36 -> 5621.57 | E36: =B36/C36 -> 0.68769056 | F36: =D36/C36 -> 0.31230944 | H36: Maiara Andrade | I36: =IFERROR( SUMIFS('Maiara Andrade'!$H:$H, 'Maiara Andrade'!$G:$G, "Em Análise", 'Maiara Andrade'!$L:$L, "=10"), "") -> 6262.01 | J36: 18000 | K36: =J36-I36 -> 11737.99 | L36: =I36/J36 -> 0.34788944 | M36: =K36/J36 -> 0.65211056 | O36: Maiara Andrade | P36: =IFERROR( SUMIFS('Maiara Andrade'!$H:$H, 'Maiara Andrade'!$G:$G, "Aguardando Pagamento", 'Maiara Andrade'!$L:$L, "=10"), "") -> 0 | Q36: 18000 | R36: =Q36-P36 -> 18000 | S36: =P36/Q36 -> 0 | T36: =R36/Q36 -> 1
A37: Marcio Jorge | B37: =IFERROR( SUMIFS('Marcio Jorge'!$H:$H, 'Marcio Jorge'!$G:$G, "Plano Fechado", 'Marcio Jorge'!$L:$L, "=10"), "") -> 10794.91 | C37: 12000 | D37: =C37-B37 -> 1205.09 | E37: =B37/C37 -> 0.89957583 | F37: =D37/C37 -> 0.10042417 | H37: Marcio Jorge | I37: =IFERROR( SUMIFS('Marcio Jorge'!$H:$H, 'Marcio Jorge'!$G:$G, "Em Análise", 'Marcio Jorge'!$L:$L, "=10"), "") -> 0 | J37: 12000 | K37: =J37-I37 -> 12000 | L37: =I37/J37 -> 0 | M37: =K37/J37 -> 1 | O37: Marcio Jorge | P37: =IFERROR( SUMIFS('Marcio Jorge'!$H:$H, 'Marcio Jorge'!$G:$G, "Aguardando Pagamento", 'Marcio Jorge'!$L:$L, "=10"), "") -> 0 | Q37: 12000 | R37: =Q37-P37 -> 12000 | S37: =P37/Q37 -> 0 | T37: =R37/Q37 -> 1
A38: Lucas Almeida | B38: =IFERROR( SUMIFS('Lucas Almeida'!$H:$H, 'Lucas Almeida'!$G:$G, "Plano Fechado", 'Lucas Almeida'!$L:$L, "=10"), "") -> 1963.8 | C38: 4500 | D38: =C38-B38 -> 2536.2 | E38: =B38/C38 -> 0.4364 | F38: =D38/C38 -> 0.5636 | H38: Lucas Almeida | I38: =IFERROR( SUMIFS('Lucas Almeida'!$H:$H, 'Lucas Almeida'!$G:$G, "Em Análise", 'Lucas Almeida'!$L:$L, "=10"), "") -> 0 | J38: 4500 | K38: =J38-I38 -> 4500 | L38: =I38/J38 -> 0 | M38: =K38/J38 -> 1 | O38: Lucas Almeida | P38: =IFERROR( SUMIFS('Lucas Almeida'!$H:$H, 'Lucas Almeida'!$G:$G, "Aguardando Pagamento", 'Lucas Almeida'!$L:$L, "=10"), "") -> 0 | Q38: 4500 | R38: =Q38-P38 -> 4500 | S38: =P38/Q38 -> 0 | T38: =R38/Q38 -> 1
A39: Roberto Ramos | B39: =IFERROR( SUMIFS('Roberto Ramos'!$H:$H, 'Roberto Ramos'!$G:$G, "Plano Fechado", 'Roberto Ramos'!$L:$L, "=10"), "") -> 2273.53 | C39: 14000 | D39: =C39-B39 -> 11726.47 | E39: =B39/C39 -> 0.162395 | F39: =D39/C39 -> 0.837605 | H39: Roberto Ramos | I39: =IFERROR( SUMIFS('Roberto Ramos'!$H:$H, 'Roberto Ramos'!$G:$G, "Em Análise", 'Roberto Ramos'!$L:$L, "=10"), "") -> 2420.14 | J39: 14000 | K39: =J39-I39 -> 11579.86 | L39: =I39/J39 -> 0.17286714 | M39: =K39/J39 -> 0.82713286 | O39: Roberto Ramos | P39: =IFERROR( SUMIFS('Roberto Ramos'!$H:$H, 'Roberto Ramos'!$G:$G, "Aguardando Pagamento", 'Roberto Ramos'!$L:$L, "=10"), "") -> 3947.49 | Q39: 14000 | R39: =Q39-P39 -> 10052.51 | S39: =P39/Q39 -> 0.28196357 | T39: =R39/Q39 -> 0.71803643
A40: Rodrigo Oliviera | B40: =IFERROR( SUMIFS('Rodrigo Oliveira'!$H:$H, 'Rodrigo Oliveira'!$G:$G, "Plano Fechado", 'Rodrigo Oliveira'!$L:$L, "=10"), "") -> 0 | C40: 4000 | D40: =C40-B40 -> 4000 | E40: =B40/C40 -> 0 | F40: =D40/C40 -> 1 | H40: Rodrigo Oliviera | I40: =IFERROR( SUMIFS('Rodrigo Oliveira'!$H:$H, 'Rodrigo Oliveira'!$G:$G, "Em Análise", 'Rodrigo Oliveira'!$L:$L, "=10"), "") -> 0 | J40: 4000 | K40: =J40-I40 -> 4000 | L40: =I40/J40 -> 0 | M40: =K40/J40 -> 1 | O40: Rodrigo Oliviera | P40: =IFERROR( SUMIFS('Rodrigo Oliveira'!$H:$H, 'Rodrigo Oliveira'!$G:$G, "Aguardando Pagamento", 'Rodrigo Oliveira'!$L:$L, "=10"), "") -> 0 | Q40: 4000 | R40: =Q40-P40 -> 4000 | S40: =P40/Q40 -> 0 | T40: =R40/Q40 -> 1
A41: Leandro Nascimento | B41: =IFERROR( SUMIFS('Leandro Nascimento'!$H:$H, 'Leandro Nascimento'!$G:$G, "Plano Fechado", 'Leandro Nascimento'!$L:$L, "=10"), "") -> 0 | C41: 2800 | D41: =C41-B41 -> 2800 | E41: =B41/C41 -> 0 | F41: =D41/C41 -> 1 | H41: Leandro Nascimento | I41: =IFERROR( SUMIFS('Leandro Nascimento'!$H:$H, 'Leandro Nascimento'!$G:$G, "Em Análise", 'Leandro Nascimento'!$L:$L, "=10"), "") -> 1578.6 | J41: 2800 | K41: =J41-I41 -> 1221.4 | L41: =I41/J41 -> 0.56378571 | M41: =K41/J41 -> 0.43621429 | O41: Leandro Nascimento | P41: =IFERROR( SUMIFS('Leandro Nascimento'!$H:$H, 'Leandro Nascimento'!$G:$G, "Aguardando Pagamento", 'Leandro Nascimento'!$L:$L, "=10"), "") -> 0 | Q41: 2800 | R41: =Q41-P41 -> 2800 | S41: =P41/Q41 -> 0 | T41: =R41/Q41 -> 1
A42: Leandro Drumond | B42: =IFERROR( SUMIFS('Leandro Drumond'!$H:$H, 'Leandro Drumond'!$G:$G, "Plano Fechado", 'Leandro Drumond'!$L:$L, "=10"), "") -> 0 | C42: 4500 | D42: =C42-B42 -> 4500 | E42: =B42/C42 -> 0 | F42: =D42/C42 -> 1 | H42: Leandro Drumond | I42: =IFERROR( SUMIFS('Leandro Drumond'!$H:$H, 'Leandro Drumond'!$G:$G, "Em Análise", 'Leandro Drumond'!$L:$L, "=10"), "") -> 0 | J42: 4500 | K42: =J42-I42 -> 4500 | L42: =I42/J42 -> 0 | M42: =K42/J42 -> 1 | O42: Leandro Drumond | P42: =IFERROR( SUMIFS('Leandro Drumond'!$H:$H, 'Leandro Drumond'!$G:$G, "Aguardando Pagamento", 'Leandro Drumond'!$L:$L, "=10"), "") -> 0 | Q42: 4500 | R42: =Q42-P42 -> 4500 | S42: =P42/Q42 -> 0 | T42: =R42/Q42 -> 1
A43: Marcelle Marcela | B43: =IFERROR( SUMIFS('Marcelle Marcela'!$H:$H, 'Marcelle Marcela'!$G:$G, "Plano Fechado", 'Marcelle Marcela'!$L:$L, "=10"), "") -> 0 | C43: 2800 | D43: =C43-B43 -> 2800 | E43: =B43/C43 -> 0 | F43: =D43/C43 -> 1 | H43: Marcelle Marcela | I43: =IFERROR( SUMIFS('Marcelle Marcela'!$H:$H, 'Marcelle Marcela'!$G:$G, "Em Análise", 'Marcelle Marcela'!$L:$L, "=10"), "") -> 0 | J43: 2800 | K43: =J43-I43 -> 2800 | L43: =I43/J43 -> 0 | M43: =K43/J43 -> 1 | O43: Marcelle Marcela | P43: =IFERROR( SUMIFS('Marcelle Marcela'!$H:$H, 'Marcelle Marcela'!$G:$G, "Aguardando Pagamento", 'Marcelle Marcela'!$L:$L, "=10"), "") -> 0 | Q43: 2800 | R43: =Q43-P43 -> 2800 | S43: =P43/Q43 -> 0 | T43: =R43/Q43 -> 1
A46: TOTAL | B46: =SUM(B30:B43) -> 84184.77 | C46: =SUM(C30:C43) -> 136100 | D46: =SUM(D30:D43) -> 51915.23 | E46: =AVERAGE(E30:E43) -> 0.41161162 | F46: =AVERAGE(F30:F43) -> 0.58838838 | H46: TOTAL | I46: =SUM(I30:I43) -> 15066.85 | J46: =SUM(J30:J43) -> 136100 | K46: =SUM(K30:K43) -> 121033.15 | L46: =AVERAGE(L30:L43) -> 0.096539133 | M46: =AVERAGE(M30:M43) -> 0.90346087 | O46: TOTAL | P46: =SUM(P30:P43) -> 3947.49 | Q46: =SUM(Q30:Q43) -> 136100 | R46: =SUM(R30:R43) -> 132152.51 | S46: =AVERAGE(S30:S43) -> 0.020140255 | T46: =AVERAGE(T30:T43) -> 0.97985974

Sheet MKT
B1: MAIO | J1: JUNHO | R1: JULHO | Z1: AGOSTO | AH1: SETEMBRO | AP1: OUTUBRO
B3: VISÃO MACRO PROSPECÇÃO LEADS | J3: VISÃO MACRO PROSPECÇÃO LEADS | R3: VISÃO MACRO PROSPECÇÃO LEADS | Z3: VISÃO MACRO PROSPECÇÃO LEADS | AH3: VISÃO MACRO PROSPECÇÃO LEADS | AP3: VISÃO MACRO PROSPECÇÃO LEADS
B4: QTD. Leads | C4: Vendas Fechadas | D4: Leads em Conversação | E4: Leads com Proposta Enviada | F4: Leads Desistentes | G4: Leads sem Resposta | H4: Faturamento | J4: QTD. Leads | K4: Vendas Fechadas | L4: Leads em Conversação | M4: Leads com Proposta Enviada | N4: Leads Desistentes | O4: Leads sem Resposta | P4: Faturamento | R4: QTD. Leads | S4: Vendas Fechadas | T4: Leads em Conversação | U4: Leads com Proposta Enviada | V4: Leads Desistentes | W4: Leads sem Resposta | X4: Faturamento | Z4: QTD. Leads | AA4: Vendas Fechadas | AB4: Leads em Conversação | AC4: Leads com Proposta Enviada | AD4: Leads Desistentes | AE4: Leads sem Resposta | AF4: Faturamento | AH4: QTD. Leads | AI4: Vendas Fechadas | AJ4: Leads em Conversação | AK4: Leads com Proposta Enviada | AL4: Leads Desistentes | AM4: Leads sem Resposta | AN4: Faturamento | AP4: QTD. Leads | AQ4: Plano Fechado | AR4: Em Análise | AS4: Aguardando Pagamento | AT4: Conversação | AU4: Proposta Enviada | AV4: Desistentes | AW4: Sem Resposta | AX4: Faturamento
B5: 401 | C5: 4 | D5: 39 | E5: 108 | F5: 18 | G5: 232 | H5: 3267.91 | J5: 1368 | K5: 61 | L5: 42 | M5: 355 | N5: 49 | O5: 670 | P5: 100469.35 | R5: 1485 | S5: 60 | T5: 52 | U5: 325 | V5: 39 | W5: 688 | X5: 90022.06 | Z5: 1241 | AA5: 63 | AB5: 80 | AC5: 253 | AD5: 46 | AE5: 511 | AF5: 64270.88 | AH5: 1447 | AI5: 62 | AJ5: 72 | AK5: 407 | AL5: 54 | AM5: 576 | AN5: 77071.27 | AP5: {=LET( abas, {"Amanda Facundo";"Bruna Mamedes";"Camila Adão";"Darlin Amorim";"Diogo Lima";"Externos";"Maiara Andrade";"Marcio Jorge";"Lucas Almeida";"Roberto Ramos";"Rodrigo Oliviera";"Leandro Nascimento";"Leandro Drumond";"Marcelle Marcela";"Anteriores";"Corretor 1";"Corretor 2";"Corretor 3";"Corretor 4";"Corretor 5"}, SUM(BYROW(abas, LAMBDA(a, COUNTIFS( INDIRECT("'"&a&"'!N:N"), ">="&DATE(2025,10,1), INDIRECT("'"&a&"'!N:N"), "<="&DATE(2025,10,31) )))) )} -> 1252 | AQ5: =SUM( COUNTIFS('Bruna Mamedes'!$A$2:$A$4000, "<>", 'Bruna Mamedes'!$N$2:$N$4000, ">01/10/2025", 'Bruna Mamedes'!$N$2:$N$4000, "<01/11/2025", 'Bruna Mamedes'!$G$2:$G$4000, "Plano Fechado"), COUNTIFS('Camila Adão'!$A$2:$A$4000, "<>", 'Camila Adão'!$N$2:$N$4000, ">01/10/2025", 'Camila Adão'!$N$2:$N$4000, "<01/11/2025", 'Camila Adão'!$G$2:$G$4000, "Plano Fechado"), COUNTIFS('Vendas Organicas'!$A$2:$A$4000, "<>", 'Vendas Organicas'!$N$2:$N$4000, ">01/10/2025", 'Vendas Organicas'!$N$2:$N$4000, "<01/11/2025", 'Vendas Organicas'!$G$2:$G$4000, "Plano Fechado"), COUNTIFS('Diogo Lima'!$A$2:$A$3999, "<>", 'Diogo Lima'!$N$2:$N$3999, ">01/10/2025", 'Diogo Lima'!$N$2:$N$3999, "<01/11/2025", 'Diogo Lima'!$G$2:$G$3999, "Plano Fechado"), COUNTIFS('Lucas Almeida'!$A$2:$A$4000, "<>", 'Lucas Almeida'!$N$2:$N$4000, ">01/10/2025", 'Lucas Almeida'!$N$2:$N$4000, "<01/11/2025", 'Lucas Almeida'!$G$2:$G$4000, "Plano Fechado"), COUNTIFS('Fernando Diamantino'!$A$2:$A$4000, "<>", 'Fernando Diamantino'!$N$2:$N$4000, ">01/10/2025", 'Fernando Diamantino'!$N$2:$N$4000, "<01/11/2025", 'Fernando Diamantino'!$G$2:$G$4000, "Plano Fechado"), COUNTIFS('Maiara Andrade'!$A$2:$A$4000, "<>", 'Maiara Andrade'!$N$2:$N$4000, ">01/10/2025", 'Maiara Andrade'!$N$2:$N$4000, "<01/11/2025", 'Maiara Andrade'!$G$2:$G$4000, "Plano Fechado"), COUNTIFS('Roberto Ramos'!$A$2:$A$4000, "<>", 'Roberto Ramos'!$N$2:$N$4000, ">01/10/2025", 'Roberto Ramos'!$N$2:$N$4000, "<01/11/2025", 'Roberto Ramos'!$G$2:$G$4000, "Plano Fechado"), COUNTIFS('Amanda Facundo'!$A$2:$A$4000, "<>", 'Amanda Facundo'!$N$2:$N$4000, ">01/10/2025", 'Amanda Facundo'!$N$2:$N$4000, "<01/11/2025", 'Amanda Facundo'!$G$2:$G$4000, "Plano Fechado"), COUNTIFS('Rodrigo Oliveira'!$A$2:$A$4000, "<>", 'Rodrigo Oliveira'!$N$2:$N$4000, ">01/10/2025", 'Rodrigo Oliveira'!$N$2:$N$4000, "<01/11/2025", 'Rodrigo Oliveira'!$G$2:$G$4000, "Plano Fechado"), COUNTIFS('Marcio Jorge'!$A$2:$A$4000, "<>", 'Marcio Jorge'!$N$2:$N$4000, ">01/10/2025", 'Marcio Jorge'!$N$2:$N$4000, "<01/11/2025", 'Marcio Jorge'!$G$2:$G$4000, "Plano Fechado"), COUNTIFS(Anteriores!$A$2:$A$3998, "<>", Anteriores!$N$2:$N$3998, ">01/10/2025", Anteriores!$N$2:$N$3998, "<01/11/2025", Anteriores!$G$2:$G$3998, "Plano Fechado"), COUNTIFS('Corretor 1'!$A$2:$A$4000, "<>", 'Corretor 1'!$N$2:$N$4000, ">01/10/2025", 'Corretor 1'!$N$2:$N$4000, "<01/11/2025", 'Corretor 1'!$G$2:$G$4000, "Plano Fechado"), COUNTIFS('Corretor 2'!$A$2:$A$4000, "<>", 'Corretor 2'!$N$2:$N$4000, ">01/10/2025", 'Corretor 2'!$N$2:$N$4000, "<01/11/2025", 'Corretor 2'!$G$2:$G$4000, "Plano Fechado"), COUNTIFS('Corretor 3'!$A$2:$A$4000, "<>", 'Corretor 3'!$N$2:$N$4000, ">01/10/2025", 'Corretor 3'!$N$2:$N$4000, "<01/11/2025", 'Corretor 3'!$G$2:$G$4000, "Plano Fechado"), COUNTIFS('Corretor 4'!$A$2:$A$4000, "<>", 'Corretor 4'!$N$2:$N$4000, ">01/10/2025", 'Corretor 4'!$N$2:$N$4000, "<01/11/2025", 'Corretor 4'!$G$2:$G$4000, "Plano Fechado"), COUNTIFS('Corretor 5'!$A$2:$A$4000, "<>", 'Corretor 5'!$N$2:$N$4000, ">01/10/2025", 'Corretor 5'!$N$2:$N$4000, "<01/11/2025", 'Corretor 5'!$G$2:$G$4000, "Plano Fechado") ) -> 46 | AR5: =SUM( COUNTIFS('Bruna Mamedes'!$A$2:$A$4000, "<>", 'Bruna Mamedes'!$N$2:$N$4000, ">01/10/2025", 'Bruna Mamedes'!$N$2:$N$4000, "<01/11/2025", 'Bruna Mamedes'!$G$2:$G$4000, "Em Análise"), COUNTIFS('Camila Adão'!$A$2:$A$4000, "<>", 'Camila Adão'!$N$2:$N$4000, ">01/10/2025", 'Camila Adão'!$N$2:$N$4000, "<01/11/2025", 'Camila Adão'!$G$2:$G$4000, "Em Análise"), COUNTIFS('Vendas Organicas'!$A$2:$A$4000, "<>", 'Vendas Organicas'!$N$2:$N$4000, ">01/10/2025", 'Vendas Organicas'!$N$2:$N$4000, "<01/11/2025", 'Vendas Organicas'!$G$2:$G$4000, "Em Análise"), COUNTIFS('Diogo Lima'!$A$2:$A$3999, "<>", 'Diogo Lima'!$N$2:$N$3999, ">01/10/2025", 'Diogo Lima'!$N$2:$N$3999, "<01/11/2025", 'Diogo Lima'!$G$2:$G$3999, "Em Análise"), COUNTIFS('Lucas Almeida'!$A$2:$A$4000, "<>", 'Lucas Almeida'!$N$2:$N$4000, ">01/10/2025", 'Lucas Almeida'!$N$2:$N$4000, "<01/11/2025", 'Lucas Almeida'!$G$2:$G$4000, "Em Análise"), COUNTIFS('Fernando Diamantino'!$A$2:$A$4000, "<>", 'Fernando Diamantino'!$N$2:$N$4000, ">01/10/2025", 'Fernando Diamantino'!$N$2:$N$4000, "<01/11/2025", 'Fernando Diamantino'!$G$2:$G$4000, "Em Análise"), COUNTIFS('Maiara Andrade'!$A$2:$A$4000, "<>", 'Maiara Andrade'!$N$2:$N$4000, ">01/10/2025", 'Maiara Andrade'!$N$2:$N$4000, "<01/11/2025", 'Maiara Andrade'!$G$2:$G$4000, "Em Análise"), COUNTIFS('Roberto Ramos'!$A$2:$A$4000, "<>", 'Roberto Ramos'!$N$2:$N$4000, ">01/10/2025", 'Roberto Ramos'!$N$2:$N$4000, "<01/11/2025", 'Roberto Ramos'!$G$2:$G$4000, "Em Análise"), COUNTIFS('Amanda Facundo'!$A$2:$A$4000, "<>", 'Amanda Facundo'!$N$2:$N$4000, ">01/10/2025", 'Amanda Facundo'!$N$2:$N$4000, "<01/11/2025", 'Amanda Facundo'!$G$2:$G$4000, "Em Análise"), COUNTIFS('Rodrigo Oliveira'!$A$2:$A$4000, "<>", 'Rodrigo Oliveira'!$N$2:$N$4000, ">01/10/2025", 'Rodrigo Oliveira'!$N$2:$N$4000, "<01/11/2025", 'Rodrigo Oliveira'!$G$2:$G$4000, "Em Análise"), COUNTIFS('Marcio Jorge'!$A$2:$A$4000, "<>", 'Marcio Jorge'!$N$2:$N$4000, ">01/10/2025", 'Marcio Jorge'!$N$2:$N$4000, "<01/11/2025", 'Marcio Jorge'!$G$2:$G$4000, "Em Análise"), COUNTIFS(Anteriores!$A$2:$A$3998, "<>", Anteriores!$N$2:$N$3998, ">01/10/2025", Anteriores!$N$2:$N$3998, "<01/11/2025", Anteriores!$G$2:$G$3998, "Em Análise"), COUNTIFS('Corretor 1'!$A$2:$A$4000, "<>", 'Corretor 1'!$N$2:$N$4000, ">01/10/2025", 'Corretor 1'!$N$2:$N$4000, "<01/11/2025", 'Corretor 1'!$G$2:$G$4000, "Em Análise"), COUNTIFS('Corretor 2'!$A$2:$A$4000, "<>", 'Corretor 2'!$N$2:$N$4000, ">01/10/2025", 'Corretor 2'!$N$2:$N$4000, "<01/11/2025", 'Corretor 2'!$G$2:$G$4000, "Em Análise"), COUNTIFS('Corretor 3'!$A$2:$A$4000, "<>", 'Corretor 3'!$N$2:$N$4000, ">01/10/2025", 'Corretor 3'!$N$2:$N$4000, "<01/11/2025", 'Corretor 3'!$G$2:$G$4000, "Em Análise"), COUNTIFS('Corretor 4'!$A$2:$A$4000, "<>", 'Corretor 4'!$N$2:$N$4000, ">01/10/2025", 'Corretor 4'!$N$2:$N$4000, "<01/11/2025", 'Corretor 4'!$G$2:$G$4000, "Em Análise"), COUNTIFS('Corretor 5'!$A$2:$A$4000, "<>", 'Corretor 5'!$N$2:$N$4000, ">01/10/2025", 'Corretor 5'!$N$2:$N$4000, "<01/11/2025", 'Corretor 5'!$G$2:$G$4000, "Em Análise") ) -> 18 | AS5: =SUM( COUNTIFS('Bruna Mamedes'!$A$2:$A$4000, "<>", 'Bruna Mamedes'!$N$2:$N$4000, ">01/10/2025", 'Bruna Mamedes'!$N$2:$N$4000, "<01/11/2025", 'Bruna Mamedes'!$G$2:$G$4000, "Aguardando Pagamento"), COUNTIFS('Camila Adão'!$A$2:$A$4000, "<>", 'Camila Adão'!$N$2:$N$4000, ">01/10/2025", 'Camila Adão'!$N$2:$N$4000, "<01/11/2025", 'Camila Adão'!$G$2:$G$4000, "Aguardando Pagamento"), COUNTIFS('Vendas Organicas'!$A$2:$A$4000, "<>", 'Vendas Organicas'!$N$2:$N$4000, ">01/10/2025", 'Vendas Organicas'!$N$2:$N$4000, "<01/11/2025", 'Vendas Organicas'!$G$2:$G$4000, "Aguardando Pagamento"), COUNTIFS('Diogo Lima'!$A$2:$A$3999, "<>", 'Diogo Lima'!$N$2:$N$3999, ">01/10/2025", 'Diogo Lima'!$N$2:$N$3999, "<01/11/2025", 'Diogo Lima'!$G$2:$G$3999, "Aguardando Pagamento"), COUNTIFS('Lucas Almeida'!$A$2:$A$4000, "<>", 'Lucas Almeida'!$N$2:$N$4000, ">01/10/2025", 'Lucas Almeida'!$N$2:$N$4000, "<01/11/2025", 'Lucas Almeida'!$G$2:$G$4000, "Aguardando Pagamento"), COUNTIFS('Fernando Diamantino'!$A$2:$A$4000, "<>", 'Fernando Diamantino'!$N$2:$N$4000, ">01/10/2025", 'Fernando Diamantino'!$N$2:$N$4000, "<01/11/2025", 'Fernando Diamantino'!$G$2:$G$4000, "Aguardando Pagamento"), COUNTIFS('Maiara Andrade'!$A$2:$A$4000, "<>", 'Maiara Andrade'!$N$2:$N$4000, ">01/10/2025", 'Maiara Andrade'!$N$2:$N$4000, "<01/11/2025", 'Maiara Andrade'!$G$2:$G$4000, "Aguardando Pagamento"), COUNTIFS('Roberto Ramos'!$A$2:$A$4000, "<>", 'Roberto Ramos'!$N$2:$N$4000, ">01/10/2025", 'Roberto Ramos'!$N$2:$N$4000, "<01/11/2025", 'Roberto Ramos'!$G$2:$G$4000, "Aguardando Pagamento"), COUNTIFS('Amanda Facundo'!$A$2:$A$4000, "<>", 'Amanda Facundo'!$N$2:$N$4000, ">01/10/2025", 'Amanda Facundo'!$N$2:$N$4000, "<01/11/2025", 'Amanda Facundo'!$G$2:$G$4000, "Aguardando Pagamento"), COUNTIFS('Rodrigo Oliveira'!$A$2:$A$4000, "<>", 'Rodrigo Oliveira'!$N$2:$N$4000, ">01/10/2025", 'Rodrigo Oliveira'!$N$2:$N$4000, "<01/11/2025", 'Rodrigo Oliveira'!$G$2:$G$4000, "Aguardando Pagamento"), COUNTIFS('Marcio Jorge'!$A$2:$A$4000, "<>", 'Marcio Jorge'!$N$2:$N$4000, ">01/10/2025", 'Marcio Jorge'!$N$2:$N$4000, "<01/11/2025", 'Marcio Jorge'!$G$2:$G$4000, "Aguardando Pagamento"), COUNTIFS(Anteriores!$A$2:$A$3998, "<>", Anteriores!$N$2:$N$3998, ">01/10/2025", Anteriores!$N$2:$N$3998, "<01/11/2025", Anteriores!$G$2:$G$3998, "Aguardando Pagamento"), COUNTIFS('Corretor 1'!$A$2:$A$4000, "<>", 'Corretor 1'!$N$2:$N$4000, ">01/10/2025", 'Corretor 1'!$N$2:$N$4000, "<01/11/2025", 'Corretor 1'!$G$2:$G$4000, "Aguardando Pagamento"), COUNTIFS('Corretor 2'!$A$2:$A$4000, "<>", 'Corretor 2'!$N$2:$N$4000, ">01/10/2025", 'Corretor 2'!$N$2:$N$4000, "<01/11/2025", 'Corretor 2'!$G$2:$G$4000, "Aguardando Pagamento"), COUNTIFS('Corretor 3'!$A$2:$A$4000, "<>", 'Corretor 3'!$N$2:$N$4000, ">01/10/2025", 'Corretor 3'!$N$2:$N$4000, "<01/11/2025", 'Corretor 3'!$G$2:$G$4000, "Aguardando Pagamento"), COUNTIFS('Corretor 4'!$A$2:$A$4000, "<>", 'Corretor 4'!$N$2:$N$4000, ">01/10/2025", 'Corretor 4'!$N$2:$N$4000, "<01/11/2025", 'Corretor 4'!$G$2:$G$4000, "Aguardando Pagamento"), COUNTIFS('Corretor 5'!$A$2:$A$4000, "<>", 'Corretor 5'!$N$2:$N$4000, ">01/10/2025", 'Corretor 5'!$N$2:$N$4000, "<01/11/2025", 'Corretor 5'!$G$2:$G$4000, "Aguardando Pagamento") ) -> 4 | AT5: =SUM( COUNTIFS('Bruna Mamedes'!$A$2:$A$4000, "<>", 'Bruna Mamedes'!$N$2:$N$4000, ">01/10/2025", 'Bruna Mamedes'!$N$2:$N$4000, "<01/11/2025", 'Bruna Mamedes'!$G$2:$G$4000, "Em conversação"), COUNTIFS('Camila Adão'!$A$2:$A$4000, "<>", 'Camila Adão'!$N$2:$N$4000, ">01/10/2025", 'Camila Adão'!$N$2:$N$4000, "<01/11/2025", 'Camila Adão'!$G$2:$G$4000, "Em conversação"), COUNTIFS('Vendas Organicas'!$A$2:$A$4000, "<>", 'Vendas Organicas'!$N$2:$N$4000, ">01/10/2025", 'Vendas Organicas'!$N$2:$N$4000, "<01/11/2025", 'Vendas Organicas'!$G$2:$G$4000, "Em conversação"), COUNTIFS('Diogo Lima'!$A$2:$A$3999, "<>", 'Diogo Lima'!$N$2:$N$3999, ">01/10/2025", 'Diogo Lima'!$N$2:$N$3999, "<01/11/2025", 'Diogo Lima'!$G$2:$G$3999, "Em conversação"), COUNTIFS('Lucas Almeida'!$A$2:$A$4000, "<>", 'Lucas Almeida'!$N$2:$N$4000, ">01/10/2025", 'Lucas Almeida'!$N$2:$N$4000, "<01/11/2025", 'Lucas Almeida'!$G$2:$G$4000, "Em conversação"), COUNTIFS('Fernando Diamantino'!$A$2:$A$4000, "<>", 'Fernando Diamantino'!$N$2:$N$4000, ">01/10/2025", 'Fernando Diamantino'!$N$2:$N$4000, "<01/11/2025", 'Fernando Diamantino'!$G$2:$G$4000, "Em conversação"), COUNTIFS('Maiara Andrade'!$A$2:$A$4000, "<>", 'Maiara Andrade'!$N$2:$N$4000, ">01/10/2025", 'Maiara Andrade'!$N$2:$N$4000, "<01/11/2025", 'Maiara Andrade'!$G$2:$G$4000, "Em conversação"), COUNTIFS('Roberto Ramos'!$A$2:$A$4000, "<>", 'Roberto Ramos'!$N$2:$N$4000, ">01/10/2025", 'Roberto Ramos'!$N$2:$N$4000, "<01/11/2025", 'Roberto Ramos'!$G$2:$G$4000, "Em conversação"), COUNTIFS('Amanda Facundo'!$A$2:$A$4000, "<>", 'Amanda Facundo'!$N$2:$N$4000, ">01/10/2025", 'Amanda Facundo'!$N$2:$N$4000, "<01/11/2025", 'Amanda Facundo'!$G$2:$G$4000, "Em conversação"), COUNTIFS('Rodrigo Oliveira'!$A$2:$A$4000, "<>", 'Rodrigo Oliveira'!$N$2:$N$4000, ">01/10/2025", 'Rodrigo Oliveira'!$N$2:$N$4000, "<01/11/2025", 'Rodrigo Oliveira'!$G$2:$G$4000, "Em conversação"), COUNTIFS('Marcio Jorge'!$A$2:$A$4000, "<>", 'Marcio Jorge'!$N$2:$N$4000, ">01/10/2025", 'Marcio Jorge'!$N$2:$N$4000, "<01/11/2025", 'Marcio Jorge'!$G$2:$G$4000, "Em conversação"), COUNTIFS(Anteriores!$A$2:$A$3998, "<>", Anteriores!$N$2:$N$3998, ">01/10/2025", Anteriores!$N$2:$N$3998, "<01/11/2025", Anteriores!$G$2:$G$3998, "Em conversação"), COUNTIFS('Corretor 1'!$A$2:$A$4000, "<>", 'Corretor 1'!$N$2:$N$4000, ">01/10/2025", 'Corretor 1'!$N$2:$N$4000, "<01/11/2025", 'Corretor 1'!$G$2:$G$4000, "Em conversação"), COUNTIFS('Corretor 2'!$A$2:$A$4000, "<>", 'Corretor 2'!$N$2:$N$4000, ">01/10/2025", 'Corretor 2'!$N$2:$N$4000, "<01/11/2025", 'Corretor 2'!$G$2:$G$4000, "Em conversação"), COUNTIFS('Corretor 3'!$A$2:$A$4000, "<>", 'Corretor 3'!$N$2:$N$4000, ">01/10/2025", 'Corretor 3'!$N$2:$N$4000, "<01/11/2025", 'Corretor 3'!$G$2:$G$4000, "Em conversação"), COUNTIFS('Corretor 4'!$A$2:$A$4000, "<>", 'Corretor 4'!$N$2:$N$4000, ">01/10/2025", 'Corretor 4'!$N$2:$N$4000, "<01/11/2025", 'Corretor 4'!$G$2:$G$4000, "Em conversação"), COUNTIFS('Corretor 5'!$A$2:$A$4000, "<>", 'Corretor 5'!$N$2:$N$4000, ">01/10/2025", 'Corretor 5'!$N$2:$N$4000, "<01/11/2025", 'Corretor 5'!$G$2:$G$4000, "Em conversação") ) -> 31 | AU5: =SUM( COUNTIFS('Bruna Mamedes'!$A$2:$A$4000, "<>", 'Bruna Mamedes'!$N$2:$N$4000, ">01/10/2025", 'Bruna Mamedes'!$N$2:$N$4000, "<01/11/2025", 'Bruna Mamedes'!$G$2:$G$4000, "Cotação Enviada"), COUNTIFS('Camila Adão'!$A$2:$A$4000, "<>", 'Camila Adão'!$N$2:$N$4000, ">01/10/2025", 'Camila Adão'!$N$2:$N$4000, "<01/11/2025", 'Camila Adão'!$G$2:$G$4000, "Cotação Enviada"), COUNTIFS('Vendas Organicas'!$A$2:$A$4000, "<>", 'Vendas Organicas'!$N$2:$N$4000, ">01/10/2025", 'Vendas Organicas'!$N$2:$N$4000, "<01/11/2025", 'Vendas Organicas'!$G$2:$G$4000, "Cotação Enviada"), COUNTIFS('Diogo Lima'!$A$2:$A$3999, "<>", 'Diogo Lima'!$N$2:$N$3999, ">01/10/2025", 'Diogo Lima'!$N$2:$N$3999, "<01/11/2025", 'Diogo Lima'!$G$2:$G$3999, "Cotação Enviada"), COUNTIFS('Lucas Almeida'!$A$2:$A$4000, "<>", 'Lucas Almeida'!$N$2:$N$4000, ">01/10/2025", 'Lucas Almeida'!$N$2:$N$4000, "<01/11/2025", 'Lucas Almeida'!$G$2:$G$4000, "Cotação Enviada"), COUNTIFS('Fernando Diamantino'!$A$2:$A$4000, "<>", 'Fernando Diamantino'!$N$2:$N$4000, ">01/10/2025", 'Fernando Diamantino'!$N$2:$N$4000, "<01/11/2025", 'Fernando Diamantino'!$G$2:$G$4000, "Cotação Enviada"), COUNTIFS('Maiara Andrade'!$A$2:$A$4000, "<>", 'Maiara Andrade'!$N$2:$N$4000, ">01/10/2025", 'Maiara Andrade'!$N$2:$N$4000, "<01/11/2025", 'Maiara Andrade'!$G$2:$G$4000, "Cotação Enviada"), COUNTIFS('Roberto Ramos'!$A$2:$A$4000, "<>", 'Roberto Ramos'!$N$2:$N$4000, ">01/10/2025", 'Roberto Ramos'!$N$2:$N$4000, "<01/11/2025", 'Roberto Ramos'!$G$2:$G$4000, "Cotação Enviada"), COUNTIFS('Amanda Facundo'!$A$2:$A$4000, "<>", 'Amanda Facundo'!$N$2:$N$4000, ">01/10/2025", 'Amanda Facundo'!$N$2:$N$4000, "<01/11/2025", 'Amanda Facundo'!$G$2:$G$4000, "Cotação Enviada"), COUNTIFS('Rodrigo Oliveira'!$A$2:$A$4000, "<>", 'Rodrigo Oliveira'!$N$2:$N$4000, ">01/10/2025", 'Rodrigo Oliveira'!$N$2:$N$4000, "<01/11/2025", 'Rodrigo Oliveira'!$G$2:$G$4000, "Cotação Enviada"), COUNTIFS('Marcio Jorge'!$A$2:$A$4000, "<>", 'Marcio Jorge'!$N$2:$N$4000, ">01/10/2025", 'Marcio Jorge'!$N$2:$N$4000, "<01/11/2025", 'Marcio Jorge'!$G$2:$G$4000, "Cotação Enviada"), COUNTIFS(Anteriores!$A$2:$A$3998, "<>", Anteriores!$N$2:$N$3998, ">01/10/2025", Anteriores!$N$2:$N$3998, "<01/11/2025", Anteriores!$G$2:$G$3998, "Cotação Enviada"), COUNTIFS('Corretor 1'!$A$2:$A$4000, "<>", 'Corretor 1'!$N$2:$N$4000, ">01/10/2025", 'Corretor 1'!$N$2:$N$4000, "<01/11/2025", 'Corretor 1'!$G$2:$G$4000, "Cotação Enviada"), COUNTIFS('Corretor 2'!$A$2:$A$4000, "<>", 'Corretor 2'!$N$2:$N$4000, ">01/10/2025", 'Corretor 2'!$N$2:$N$4000, "<01/11/2025", 'Corretor 2'!$G$2:$G$4000, "Cotação Enviada"), COUNTIFS('Corretor 3'!$A$2:$A$4000, "<>", 'Corretor 3'!$N$2:$N$4000, ">01/10/2025", 'Corretor 3'!$N$2:$N$4000, "<01/11/2025", 'Corretor 3'!$G$2:$G$4000, "Cotação Enviada"), COUNTIFS('Corretor 4'!$A$2:$A$4000, "<>", 'Corretor 4'!$N$2:$N$4000, ">01/10/2025", 'Corretor 4'!$N$2:$N$4000, "<01/11/2025", 'Corretor 4'!$G$2:$G$4000, "Cotação Enviada"), COUNTIFS('Corretor 5'!$A$2:$A$4000, "<>", 'Corretor 5'!$N$2:$N$4000, ">01/10/2025", 'Corretor 5'!$N$2:$N$4000, "<01/11/2025", 'Corretor 5'!$G$2:$G$4000, "Cotação Enviada") ) -> 267 | AV5: =SUM( COUNTIFS('Bruna Mamedes'!$A$2:$A$4000, "<>", 'Bruna Mamedes'!$N$2:$N$4000, ">01/10/2025", 'Bruna Mamedes'!$N$2:$N$4000, "<01/11/2025", 'Bruna Mamedes'!$G$2:$G$4000, "Desistência"), COUNTIFS('Camila Adão'!$A$2:$A$4000, "<>", 'Camila Adão'!$N$2:$N$4000, ">01/10/2025", 'Camila Adão'!$N$2:$N$4000, "<01/11/2025", 'Camila Adão'!$G$2:$G$4000, "Desistência"), COUNTIFS('Vendas Organicas'!$A$2:$A$4000, "<>", 'Vendas Organicas'!$N$2:$N$4000, ">01/10/2025", 'Vendas Organicas'!$N$2:$N$4000, "<01/11/2025", 'Vendas Organicas'!$G$2:$G$4000, "Desistência"), COUNTIFS('Diogo Lima'!$A$2:$A$3999, "<>", 'Diogo Lima'!$N$2:$N$3999, ">01/10/2025", 'Diogo Lima'!$N$2:$N$3999, "<01/11/2025", 'Diogo Lima'!$G$2:$G$3999, "Desistência"), COUNTIFS('Lucas Almeida'!$A$2:$A$4000, "<>", 'Lucas Almeida'!$N$2:$N$4000, ">01/10/2025", 'Lucas Almeida'!$N$2:$N$4000, "<01/11/2025", 'Lucas Almeida'!$G$2:$G$4000, "Desistência"), COUNTIFS('Fernando Diamantino'!$A$2:$A$4000, "<>", 'Fernando Diamantino'!$N$2:$N$4000, ">01/10/2025", 'Fernando Diamantino'!$N$2:$N$4000, "<01/11/2025", 'Fernando Diamantino'!$G$2:$G$4000, "Desistência"), COUNTIFS('Maiara Andrade'!$A$2:$A$4000, "<>", 'Maiara Andrade'!$N$2:$N$4000, ">01/10/2025", 'Maiara Andrade'!$N$2:$N$4000, "<01/11/2025", 'Maiara Andrade'!$G$2:$G$4000, "Desistência"), COUNTIFS('Roberto Ramos'!$A$2:$A$4000, "<>", 'Roberto Ramos'!$N$2:$N$4000, ">01/10/2025", 'Roberto Ramos'!$N$2:$N$4000, "<01/11/2025", 'Roberto Ramos'!$G$2:$G$4000, "Desistência"), COUNTIFS('Amanda Facundo'!$A$2:$A$4000, "<>", 'Amanda Facundo'!$N$2:$N$4000, ">01/10/2025", 'Amanda Facundo'!$N$2:$N$4000, "<01/11/2025", 'Amanda Facundo'!$G$2:$G$4000, "Desistência"), COUNTIFS('Rodrigo Oliveira'!$A$2:$A$4000, "<>", 'Rodrigo Oliveira'!$N$2:$N$4000, ">01/10/2025", 'Rodrigo Oliveira'!$N$2:$N$4000, "<01/11/2025", 'Rodrigo Oliveira'!$G$2:$G$4000, "Desistência"), COUNTIFS('Marcio Jorge'!$A$2:$A$4000, "<>", 'Marcio Jorge'!$N$2:$N$4000, ">01/10/2025", 'Marcio Jorge'!$N$2:$N$4000, "<01/11/2025", 'Marcio Jorge'!$G$2:$G$4000, "Desistência"), COUNTIFS(Anteriores!$A$2:$A$3998, "<>", Anteriores!$N$2:$N$3998, ">01/10/2025", Anteriores!$N$2:$N$3998, "<01/11/2025", Anteriores!$G$2:$G$3998, "Desistência"), COUNTIFS('Corretor 1'!$A$2:$A$4000, "<>", 'Corretor 1'!$N$2:$N$4000, ">01/10/2025", 'Corretor 1'!$N$2:$N$4000, "<01/11/2025", 'Corretor 1'!$G$2:$G$4000, "Desistência"), COUNTIFS('Corretor 2'!$A$2:$A$4000, "<>", 'Corretor 2'!$N$2:$N$4000, ">01/10/2025", 'Corretor 2'!$N$2:$N$4000, "<01/11/2025", 'Corretor 2'!$G$2:$G$4000, "Desistência"), COUNTIFS('Corretor 3'!$A$2:$A$4000, "<>", 'Corretor 3'!$N$2:$N$4000, ">01/10/2025", 'Corretor 3'!$N$2:$N$4000, "<01/11/2025", 'Corretor 3'!$G$2:$G$4000, "Desistência"), COUNTIFS('Corretor 4'!$A$2:$A$4000, "<>", 'Corretor 4'!$N$2:$N$4000, ">01/10/2025", 'Corretor 4'!$N$2:$N$4000, "<01/11/2025", 'Corretor 4'!$G$2:$G$4000, "Desistência"), COUNTIFS('Corretor 5'!$A$2:$A$4000, "<>", 'Corretor 5'!$N$2:$N$4000, ">01/10/2025", 'Corretor 5'!$N$2:$N$4000, "<01/11/2025", 'Corretor 5'!$G$2:$G$4000, "Desistência") ) -> 73 | AW5: =SUM( COUNTIFS('Bruna Mamedes'!$A$2:$A$4000, "<>", 'Bruna Mamedes'!$N$2:$N$4000, ">01/10/2025", 'Bruna Mamedes'!$N$2:$N$4000, "<01/11/2025", 'Bruna Mamedes'!$G$2:$G$4000, "Não Respondeu"), COUNTIFS('Camila Adão'!$A$2:$A$4000, "<>", 'Camila Adão'!$N$2:$N$4000, ">01/10/2025", 'Camila Adão'!$N$2:$N$4000, "<01/11/2025", 'Camila Adão'!$G$2:$G$4000, "Não Respondeu"), COUNTIFS('Vendas Organicas'!$A$2:$A$4000, "<>", 'Vendas Organicas'!$N$2:$N$4000, ">01/10/2025", 'Vendas Organicas'!$N$2:$N$4000, "<01/11/2025", 'Vendas Organicas'!$G$2:$G$4000, "Não Respondeu"), COUNTIFS('Diogo Lima'!$A$2:$A$3999, "<>", 'Diogo Lima'!$N$2:$N$3999, ">01/10/2025", 'Diogo Lima'!$N$2:$N$3999, "<01/11/2025", 'Diogo Lima'!$G$2:$G$3999, "Não Respondeu"), COUNTIFS('Lucas Almeida'!$A$2:$A$4000, "<>", 'Lucas Almeida'!$N$2:$N$4000, ">01/10/2025", 'Lucas Almeida'!$N$2:$N$4000, "<01/11/2025", 'Lucas Almeida'!$G$2:$G$4000, "Não Respondeu"), COUNTIFS('Fernando Diamantino'!$A$2:$A$4000, "<>", 'Fernando Diamantino'!$N$2:$N$4000, ">01/10/2025", 'Fernando Diamantino'!$N$2:$N$4000, "<01/11/2025", 'Fernando Diamantino'!$G$2:$G$4000, "Não Respondeu"), COUNTIFS('Maiara Andrade'!$A$2:$A$4000, "<>", 'Maiara Andrade'!$N$2:$N$4000, ">01/10/2025", 'Maiara Andrade'!$N$2:$N$4000, "<01/11/2025", 'Maiara Andrade'!$G$2:$G$4000, "Não Respondeu"), COUNTIFS('Roberto Ramos'!$A$2:$A$4000, "<>", 'Roberto Ramos'!$N$2:$N$4000, ">01/10/2025", 'Roberto Ramos'!$N$2:$N$4000, "<01/11/2025", 'Roberto Ramos'!$G$2:$G$4000, "Não Respondeu"), COUNTIFS('Amanda Facundo'!$A$2:$A$4000, "<>", 'Amanda Facundo'!$N$2:$N$4000, ">01/10/2025", 'Amanda Facundo'!$N$2:$N$4000, "<01/11/2025", 'Amanda Facundo'!$G$2:$G$4000, "Não Respondeu"), COUNTIFS('Rodrigo Oliveira'!$A$2:$A$4000, "<>", 'Rodrigo Oliveira'!$N$2:$N$4000, ">01/10/2025", 'Rodrigo Oliveira'!$N$2:$N$4000, "<01/11/2025", 'Rodrigo Oliveira'!$G$2:$G$4000, "Não Respondeu"), COUNTIFS('Marcio Jorge'!$A$2:$A$4000, "<>", 'Marcio Jorge'!$N$2:$N$4000, ">01/10/2025", 'Marcio Jorge'!$N$2:$N$4000, "<01/11/2025", 'Marcio Jorge'!$G$2:$G$4000, "Não Respondeu"), COUNTIFS(Anteriores!$A$2:$A$3998, "<>", Anteriores!$N$2:$N$3998, ">01/10/2025", Anteriores!$N$2:$N$3998, "<01/11/2025", Anteriores!$G$2:$G$3998, "Não Respondeu"), COUNTIFS('Corretor 1'!$A$2:$A$4000, "<>", 'Corretor 1'!$N$2:$N$4000, ">01/10/2025", 'Corretor 1'!$N$2:$N$4000, "<01/11/2025", 'Corretor 1'!$G$2:$G$4000, "Não Respondeu"), COUNTIFS('Corretor 2'!$A$2:$A$4000, "<>", 'Corretor 2'!$N$2:$N$4000, ">01/10/2025", 'Corretor 2'!$N$2:$N$4000, "<01/11/2025", 'Corretor 2'!$G$2:$G$4000, "Não Respondeu"), COUNTIFS('Corretor 3'!$A$2:$A$4000, "<>", 'Corretor 3'!$N$2:$N$4000, ">01/10/2025", 'Corretor 3'!$N$2:$N$4000, "<01/11/2025", 'Corretor 3'!$G$2:$G$4000, "Não Respondeu"), COUNTIFS('Corretor 4'!$A$2:$A$4000, "<>", 'Corretor 4'!$N$2:$N$4000, ">01/10/2025", 'Corretor 4'!$N$2:$N$4000, "<01/11/2025", 'Corretor 4'!$G$2:$G$4000, "Não Respondeu"), COUNTIFS('Corretor 5'!$A$2:$A$4000, "<>", 'Corretor 5'!$N$2:$N$4000, ">01/10/2025", 'Corretor 5'!$N$2:$N$4000, "<01/11/2025", 'Corretor 5'!$G$2:$G$4000, "Não Respondeu") ) -> 428 | AX5: =SUM( SUMIFS('Bruna Mamedes'!$H$2:$H$4000, 'Bruna Mamedes'!$G$2:$G$4000, "Plano Fechado", 'Bruna Mamedes'!$N$2:$N$4000, ">=01/10/2025", 'Bruna Mamedes'!$N$2:$N$4000, "<=31/10/2025"), SUMIFS('Camila Adão'!$H$2:$H$1997, 'Camila Adão'!$G$2:$G$1997, "Plano Fechado", 'Camila Adão'!$N$2:$N$1997, ">=01/10/2025", 'Camila Adão'!$N$2:$N$1997, "<=31/10/2025"), SUMIFS('Vendas Organicas'!$H$2:$H$3000, 'Vendas Organicas'!$G$2:$G$3000, "Plano Fechado", 'Vendas Organicas'!$N$2:$N$3000, ">=01/10/2025", 'Vendas Organicas'!$N$2:$N$3000, "<=31/10/2025"), SUMIFS('Diogo Lima'!$H$2:$H$1996, 'Diogo Lima'!$G$2:$G$1996, "Plano Fechado", 'Diogo Lima'!$N$2:$N$1996, ">=01/10/2025", 'Diogo Lima'!$N$2:$N$1996, "<=31/10/2025"), SUMIFS('Lucas Almeida'!$H$2:$H$4000, 'Lucas Almeida'!$G$2:$G$4000, "Plano Fechado", 'Lucas Almeida'!$N$2:$N$4000, ">=01/10/2025", 'Lucas Almeida'!$N$2:$N$4000, "<=31/10/2025"), SUMIFS('Fernando Diamantino'!$H$2:$H$1999, 'Fernando Diamantino'!$G$2:$G$1999, "Plano Fechado", 'Fernando Diamantino'!$N$2:$N$1999, ">=01/10/2025", 'Fernando Diamantino'!$N$2:$N$1999, "<=31/10/2025"), SUMIFS('Maiara Andrade'!$H$2:$H$4000, 'Maiara Andrade'!$G$2:$G$4000, "Plano Fechado", 'Maiara Andrade'!$N$2:$N$4000, ">=01/10/2025", 'Maiara Andrade'!$N$2:$N$4000, "<=31/10/2025"), SUMIFS('Roberto Ramos'!$H$2:$H$4000, 'Roberto Ramos'!$G$2:$G$4000, "Plano Fechado", 'Roberto Ramos'!$N$2:$N$4000, ">=01/10/2025", 'Roberto Ramos'!$N$2:$N$4000, "<=31/10/2025"), SUMIFS('Amanda Facundo'!$H$2:$H$1999, 'Amanda Facundo'!$G$2:$G$1999, "Plano Fechado", 'Amanda Facundo'!$N$2:$N$1999, ">=01/10/2025", 'Amanda Facundo'!$N$2:$N$1999, "<=31/10/2025"), SUMIFS('Rodrigo Oliveira'!$H$2:$H$4000, 'Rodrigo Oliveira'!$G$2:$G$4000, "Plano Fechado", 'Rodrigo Oliveira'!$N$2:$N$4000, ">=01/10/2025", 'Rodrigo Oliveira'!$N$2:$N$4000, "<=31/10/2025"), SUMIFS(Anteriores!$H$2:$H$3998, Anteriores!$G$2:$G$3998, "Plano Fechado", Anteriores!$N$2:$N$3998, ">=01/10/2025", Anteriores!$N$2:$N$3998, "<=31/10/2025"), SUMIFS('Corretor 1'!$H$2:$H$4000, 'Corretor 1'!$G$2:$G$4000, "Plano Fechado", 'Corretor 1'!$N$2:$N$4000, ">=01/10/2025", 'Corretor 1'!$N$2:$N$4000, "<=31/10/2025"), SUMIFS('Corretor 2'!$H$2:$H$4000, 'Corretor 2'!$G$2:$G$4000, "Plano Fechado", 'Corretor 2'!$N$2:$N$4000, ">=01/10/2025", 'Corretor 2'!$N$2:$N$4000, "<=31/10/2025"), SUMIFS('Corretor 3'!$H$2:$H$4000, 'Corretor 3'!$G$2:$G$4000, "Plano Fechado", 'Corretor 3'!$N$2:$N$4000, ">=01/10/2025", 'Corretor 3'!$N$2:$N$4000, "<=31/10/2025"), SUMIFS('Corretor 4'!$H$2:$H$4000, 'Corretor 4'!$G$2:$G$4000, "Plano Fechado", 'Corretor 4'!$N$2:$N$4000, ">=01/10/2025", 'Corretor 4'!$N$2:$N$4000, "<=31/10/2025"), SUMIFS('Corretor 5'!$H$2:$H$4000, 'Corretor 5'!$G$2:$G$4000, "Plano Fechado", 'Corretor 5'!$N$2:$N$4000, ">=01/10/2025", 'Corretor 5'!$N$2:$N$4000, "<=31/10/2025") ) -> 77911.36
C6: 0.01 | D6: 0.097 | E6: 0.269 | F6: 0.045 | G6: 0.579 | K6: 0.045 | L6: 0.031 | M6: 0.26 | N6: 0.036 | O6: 0.49 | S6: 0.04 | T6: 0.035 | U6: 0.219 | V6: 0.026 | W6: 0.463 | AA6: 0.051 | AB6: 0.064 | AC6: 0.204 | AD6: 0.037 | AE6: 0.412 | AI6: 0.043 | AJ6: 0.05 | AK6: 0.281 | AL6: 0.037 | AM6: 0.398 | AQ6: =(AQ5/AP5) -> 0.036741214 | AR6: =AR5/AP5 -> 0.014376997 | AS6: =AS5/AP5 -> 0.0031948882 | AT6: =(AT5/AP5) -> 0.024760383 | AU6: =AU5/AP5 -> 0.21325879 | AV6: =AV5/AP5 -> 0.058306709 | AW6: =AW5/AP5 -> 0.34185304
B8: LEADS INSTAGRAM | J8: LEADS INSTAGRAM | R8: LEADS INSTAGRAM | Z8: LEADS INSTAGRAM | AH8: LEADS INSTAGRAM | AP8: LEADS INSTAGRAM
B9: QTD. Leads | C9: Vendas Fechadas | D9: Leads em Conversação | E9: Leads com Proposta Enviada | F9: Leads Desistentes | G9: Leads sem Resposta | H9: Faturamento | J9: QTD. Leads | K9: Vendas Fechadas | L9: Leads em Conversação | M9: Leads com Proposta Enviada | N9: Leads Desistentes | O9: Leads sem Resposta | P9: Faturamento | R9: QTD. Leads | S9: Vendas Fechadas | T9: Leads em Conversação | U9: Leads com Proposta Enviada | V9: Leads Desistentes | W9: Leads sem Resposta | X9: Faturamento | Z9: QTD. Leads | AA9: Vendas Fechadas | AB9: Leads em Conversação | AC9: Leads com Proposta Enviada | AD9: Leads Desistentes | AE9: Leads sem Resposta | AF9: Faturamento | AH9: QTD. Leads | AI9: Vendas Fechadas | AJ9: Leads em Conversação | AK9: Leads com Proposta Enviada | AL9: Leads Desistentes | AM9: Leads sem Resposta | AN9: Faturamento | AP9: QTD. Leads | AQ9: Plano Fechado | AR9: Em Análise | AS9: Aguardando Pagamento | AT9: Conversação | AU9: Proposta Enviada | AV9: Desistentes | AW9: Sem Resposta | AX9: Faturamento
